Rust 将错误组合成两个主要类别：**可恢复错误**（*recoverable*）和 **不可恢复错误**（*unrecoverable*）。可恢复错误通常代表向用户报告错误和重试操作是合理的情况，比如未找到文件。不可恢复错误通常是 bug 的同义词，比如尝试访问超过数组结尾的位置。

许多语言不区分上面两种错误，并且使用类似*异常*的机制来处理它们。Rust没有异常机制，但有可恢复错误 `Result<T, E>` ，和不可恢复错误 `panic!`。

## 9.1 `panic!`与不可恢复的错误

`panic!`是一个宏。执行这个宏时，程序打印一个错误信息，展开并清理栈数据，然后退出。出现这种情况一般是程序检测到了一个无法处理的bug。

panic的默认行为是**展开**（unwinding），这意味着程序会回溯栈并清理所有函数的数据，回收内存。另一种选择是直接**终止**（abort），程序将立即退出，内存交由操作系统清理。展开机制会在编译出的可执行文件中占用额外的空间，而终止机制不会。如果想切换到展开，可以在*Cargo.toml*中的`[profile]`部分增加`panic = 'abort'`。

例如，如果你想要在release模式中 panic 时直接终止：

```toml
[profile.release]
panic = 'abort'
```

我们可以手动调用`panic!`宏：

```rust
fm main() {
    panic!("crash and burn");
}
```

运行程序将会出现类似这样的输出：

```bash
$ cargo run
   Compiling panic v0.1.0 (file:///projects/panic)
    Finished dev [unoptimized + debuginfo] target(s) in 0.25s
     Running `target/debug/panic`
thread 'main' panicked at 'crash and burn', src/main.rs:2:5
note: Run with `RUST_BACKTRACE=1` for a backtrace.
```

### 使用`panic!`的backtrace

以vector索引越界为例：

```rust
fn main() {
    let v = vec![1, 2, 3];
    v[99];
}
```

这种情况下C/C++会尝试提供索引位置的值，即使该位置已经不在`v`的范围之内。这里面有安全风险，攻击者可能像这样操作索引来读取储存在数组后面不被允许的数据。

Rust遇到这种情况会panic。

*backtrace* 是一个执行到目前位置所有被调用的函数的列表。Rust 的 backtrace 跟其他语言中的一样：阅读 backtrace 的关键是从头开始读直到发现你编写的文件。这就是问题的发源地。这一行往上是你的代码所调用的代码；往下则是调用你的代码的代码。这些行可能包含核心 Rust 代码，标准库代码或用到的 crate 代码。

## 9.2 `Result`与可恢复的错误

我们已经在第二章用过一次`Result`枚举。它有两个成员：`Ok`和`Err`。

`Result`在prelude之中。

```rust
enum Result<T, E> {
    Ok(T),
    Err(E),
}
```

例子：

```rust
use std::fs::File;

fn main() {
    let f = File::open("hello.txt");
}
```

`File::open`返回一个`Result`，如果打开成功，`f`将是一个包含文件句柄的`Ok`实例。如果打开失败（文件不存在，没有权限，等等），`f`将是一个包含详细出错信息的`Err`实例。

```rust
use std::fs::File;

fn main() {
    let f = File::open("hello.txt");

    let f = match f {
        Ok(file) => file,
        Err(error) => {
            panic!("Problem opening the file: {:?}", error)
        },
    };
}
```

### 匹配不同的错误

上面代码的改进版：

```rust
use std::fs::File;
use std::io::ErrorKind;

fn main() {
    let f = File::open("hello.txt");

    let f = match f {
        Ok(file) => file,
        Err(error) => match error.kind() {
            ErrorKind::NotFound => match File::create("hello.txt") {
                Ok(fc) => fc,
                Err(e) => panic!("Problem creating the file: {:?}", e),
            },
            other_error => panic!("Problem opening the file: {:?}", other_error),
        },
    };	//let f = match f {...}
}
```

这段代码在文件不存在时尝试创建，在创建失败或者文件没有权限打开时panic。

这段代码包含大量的`match`。一个老练的Rustacean可能会这样写：

```rust
use std::fs::File;
use std::io::ErrorKind;

fn main() {
    let f = File::open("hello.txt").unwrap_or_else(|error| {
        if error.kind() == ErrorKind::NotFound {
            File::create("hello.txt").unwrap_or_else(|error| {
                panic!("Problem creating the file: {:?}", error);
            })
        } else {
            panic!("Problem opening the file: {:?}", error);
        }
    });
}
```

详见十三章。

### 失败时panic的简写：unwrap和expect

`match`显得有些啰嗦，且可读性一般。

`Result<T, E>`定义了很多辅助方法，其中一个是`unwrap`。如果`Result`成员是`Ok`，它返回`Ok`中的值；如果`Result`成员是`Err`，它会调用`panic!`。

```rust
let f = File::open("hello.txt").unwrap();
```

如果文件无法打开，程序将panic；否则`f`将得到文件句柄。

`unwrap`的简单改进版本是`expect`。与`unwrap`不同的是，`expect`允许我们自定义`panic!`信息。

```rust
let f = File::open("hello.txt").expect("Failed to open hello.txt");
```

### 传播错误

所谓传播错误，是指函数将错误传递给调用者。

```rust
use std::io;
use std::io::Read;
use std::fs::File;

fn read_username_from_file() -> Result<String, io::Error> {
    let f = File::open("hello.txt");

    let mut f = match f {
        Ok(file) => file,
        Err(e) => return Err(e),
    };

    let mut s = String::new();

    match f.read_to_string(&mut s) {
        Ok(_) => Ok(s),
        Err(e) => Err(e),
    }
}
```

### 传播错误的简写：`?`运算符

下面这段代码实现了与上面代码完全相同的效果：

```rust
use std::io;
use std::io::Read;
use std::fs::File;

fn read_username_from_file() -> Result<String, io::Error> {
    let mut f = File::open("hello.txt")?;
    let mut s = String::new();
    f.read_to_string(&mut s)?;
    Ok(s)
}
```

如果 `Result` 的值是 `Ok`，表达式将会返回 `Ok` 中的值而程序将继续执行。如果值是 `Err`，`Err` 中的值将作为整个函数的返回值，就好像使用了 `return` 关键字一样，这样错误值就被传播给了调用者。



（本节未完，待续。2021-12-02）

## 9.3 `panic!`还是不`panic!`

### 示例、代码原型和测试都非常适合`panic`

### 当我们比编译器知道更多的情况

（本节未完，待续。2021-12-02）
